<?xml version="1.0" encoding="utf-8"?>
<mujoco>
	<compiler angle="radian" coordinate="local" meshdir="../stls/fetch" texturedir="../textures"></compiler>
	<option timestep="0.002">
		<flag warmstart="enable"></flag>
	</option>
	<visual>
		<map znear="0.01"></map><!--调节znear的值可以改善fetch 远视的毛病-->
	</visual>

	<asset>
		<texture type="skybox" builtin="gradient" rgb1="0.3 0.5 0.7" rgb2="0 0 0" width="512" height="512"/>
		<texture name="texplane" type="2d" builtin="checker" rgb1=".2 .3 .4" rgb2=".1 0.15 0.2"
		    width="512" height="512" mark="cross" markrgb=".8 .8 .8"/>
		<material name="matplane" reflectance="0.3" texture="texplane" texrepeat="1 1" texuniform="true"/>
	</asset>
	<include file="shared.xml"></include>
	
	<worldbody>
		<geom name="ground" type="plane" size="100 100 1" pos="0 0 0" quat="1 0 0 0" material="matplane" condim="1"/>
		<geom name="floor0" pos="0.8 0.75 0" size="0.85 0.7 1" type="plane" condim="3" material="floor_mat"></geom>
		<body name="floor0" pos="0.8 0.75 0">
			<site name="target0" pos="0 0 0.5" size="0.02 0.02 0.02" rgba="0 1 0 1" type="sphere"></site>
		</body>

		<include file="robot.xml"></include>
		
		<body pos="1.3 0.75 0.2" name="table0">
			<geom name="table0" size="0.4 0.6 0.2" type="box" mass="2000" material="table_mat"></geom>
		</body>

		<!--<body pos="1.2 0.25 0.6" name="obtacle00">
			<geom name="obstacle00" size="0.05 0.02 0.3" type="box" mass="2000" rgba="0.2 0.4 0.7 1.0"></geom>
		</body>

		<body pos="1.1 0.55 0.6" name="obtacle01">
			<geom name="obstacle01" size="0.02 0.05 0.43" type="box" mass="2000" rgba="0.2 0.4 0.7 1.0"></geom>
		</body>-->

		<body pos="1.2 0.75 0.45" name="obtacle02">
			<geom name="obstacle02" size="0.04 0.04 0.04" type="box" mass="2000" rgba="0.2 0.4 0.7 1.0"></geom>
			<joint axis="1 0 0" name="obstacle02:x" type="slide"/>
            <joint axis="0 1 0" name="obstacle02:y" type="slide"/>
			<joint axis="0 0 1" name="obstacle02:z" type="slide"/>
		</body>

		<!--<body pos="1.1 1.15 0.6" name="obtacle03">
			<geom name="obstacle03" size="0.02 0.02 0.35" type="box" mass="2000" rgba="0.2 0.4 0.7 1.0"></geom>
		</body>-

		<body pos="1.6 0.25 0.6" name="obtacle10">
			<geom name="obstacle10" size="0.02 0.02 0.7" type="box" mass="2000" rgba="0.2 0.4 0.7 1.0"></geom>
		</body>

		<body pos="1.5 0.55 0.6" name="obtacle11">
			<geom name="obstacle11" size="0.04 0.04 0.25" type="box" mass="2000" rgba="0.2 0.4 0.7 1.0"></geom>
		</body>

		<body pos="1.6 0.85 0.6" name="obtacle12">
			<geom name="obstacle12" size="0.05 0.03 0.4" type="box" mass="2000" rgba="0.2 0.4 0.7 1.0"></geom>
		</body>

		<body pos="1.5 1.15 0.6" name="obtacle13">
			<geom name="obstacle13" size="0.03 0.04 0.75" type="box" mass="2000" rgba="0.2 0.4 0.7 1.0"></geom>
		</body>-->

		<light directional="true" ambient="0.2 0.2 0.2" diffuse="0.8 0.8 0.8" specular="0.3 0.3 0.3" castshadow="false" pos="0 0 4" dir="0 0 -1" name="light0"></light>
	</worldbody>
	
	<actuator></actuator>
</mujoco>
